Failure # 1 (occurred at 2022-06-17_19-30-08)
[36mray::ImplicitFunc.train()[39m (pid=546893, ip=192.168.50.164, repr=train_and_validate)
  File "/home/sandbox-2/anaconda3/envs/dl/lib/python3.6/site-packages/ray/tune/trainable.py", line 360, in train
    result = self.step()
  File "/home/sandbox-2/anaconda3/envs/dl/lib/python3.6/site-packages/ray/tune/function_runner.py", line 404, in step
    self._report_thread_runner_error(block=True)
  File "/home/sandbox-2/anaconda3/envs/dl/lib/python3.6/site-packages/ray/tune/function_runner.py", line 574, in _report_thread_runner_error
    raise e
  File "/home/sandbox-2/anaconda3/envs/dl/lib/python3.6/site-packages/ray/tune/function_runner.py", line 277, in run
    self._entrypoint()
  File "/home/sandbox-2/anaconda3/envs/dl/lib/python3.6/site-packages/ray/tune/function_runner.py", line 352, in entrypoint
    self._status_reporter.get_checkpoint(),
  File "/home/sandbox-2/anaconda3/envs/dl/lib/python3.6/site-packages/ray/tune/function_runner.py", line 645, in _trainable_func
    output = fn()
  File "search_and_train.py", line 25, in train_and_validate
    train_loader, validation_loader, test_loader = get_datasets(DATA_ROOT_DIR,CSV_DIR,config['batch_size'],NUM_WORKERS)
ValueError: too many values to unpack (expected 3)
